WARNING:django.request:Method Not Allowed: /api/search/
ERROR:django.request:Internal Server Error: /api/search/
Traceback (most recent call last):
  File "C:\Users\elisa\OneDrive\Documents\GitHub\fm-dashboard\env\lib\site-packages\django\core\handlers\exception.py", line 47, in inner
    response = get_response(request)
  File "C:\Users\elisa\OneDrive\Documents\GitHub\fm-dashboard\env\lib\site-packages\django\core\handlers\base.py", line 181, in _get_response
    response = wrapped_callback(request, *callback_args, **callback_kwargs)
  File "C:\Users\elisa\OneDrive\Documents\GitHub\fm-dashboard\env\lib\site-packages\django\views\decorators\csrf.py", line 54, in wrapped_view
    return view_func(*args, **kwargs)
  File "C:\Users\elisa\OneDrive\Documents\GitHub\fm-dashboard\env\lib\site-packages\django\views\generic\base.py", line 70, in view
    return self.dispatch(request, *args, **kwargs)
  File "C:\Users\elisa\OneDrive\Documents\GitHub\fm-dashboard\env\lib\site-packages\rest_framework\views.py", line 511, in dispatch
    self.response = self.finalize_response(request, response, *args, **kwargs)
  File "C:\Users\elisa\OneDrive\Documents\GitHub\fm-dashboard\env\lib\site-packages\rest_framework\views.py", line 423, in finalize_response
    assert isinstance(response, HttpResponseBase), (
AssertionError: Expected a `Response`, `HttpResponse` or `HttpStreamingResponse` to be returned from the view, but received a `<class 'NoneType'>`
INFO:django.utils.autoreload:C:\Users\elisa\OneDrive\Documents\GitHub\research-for-all\rfa\core\views.py changed, reloading.
INFO:django.utils.autoreload:C:\Users\elisa\OneDrive\Documents\GitHub\research-for-all\rfa\core\views.py changed, reloading.
INFO:django.utils.autoreload:C:\Users\elisa\OneDrive\Documents\GitHub\research-for-all\rfa\core\views.py changed, reloading.
INFO:django.utils.autoreload:C:\Users\elisa\OneDrive\Documents\GitHub\research-for-all\rfa\core\views.py changed, reloading.
ERROR:django.request:Internal Server Error: /api/search/
Traceback (most recent call last):
  File "C:\Users\elisa\OneDrive\Documents\GitHub\fm-dashboard\env\lib\site-packages\django\core\handlers\exception.py", line 47, in inner
    response = get_response(request)
  File "C:\Users\elisa\OneDrive\Documents\GitHub\fm-dashboard\env\lib\site-packages\django\core\handlers\base.py", line 181, in _get_response
    response = wrapped_callback(request, *callback_args, **callback_kwargs)
  File "C:\Users\elisa\OneDrive\Documents\GitHub\fm-dashboard\env\lib\site-packages\django\views\decorators\csrf.py", line 54, in wrapped_view
    return view_func(*args, **kwargs)
  File "C:\Users\elisa\OneDrive\Documents\GitHub\fm-dashboard\env\lib\site-packages\django\views\generic\base.py", line 70, in view
    return self.dispatch(request, *args, **kwargs)
  File "C:\Users\elisa\OneDrive\Documents\GitHub\fm-dashboard\env\lib\site-packages\rest_framework\views.py", line 509, in dispatch
    response = self.handle_exception(exc)
  File "C:\Users\elisa\OneDrive\Documents\GitHub\fm-dashboard\env\lib\site-packages\rest_framework\views.py", line 469, in handle_exception
    self.raise_uncaught_exception(exc)
  File "C:\Users\elisa\OneDrive\Documents\GitHub\fm-dashboard\env\lib\site-packages\rest_framework\views.py", line 480, in raise_uncaught_exception
    raise exc
  File "C:\Users\elisa\OneDrive\Documents\GitHub\fm-dashboard\env\lib\site-packages\rest_framework\views.py", line 506, in dispatch
    response = handler(request, *args, **kwargs)
  File "C:\Users\elisa\OneDrive\Documents\GitHub\research-for-all\rfa\core\views.py", line 22, in get
    search_query = scholarly.search_pubs(search_term)
  File "C:\Users\elisa\OneDrive\Documents\GitHub\fm-dashboard\env\lib\site-packages\scholarly\_scholarly.py", line 123, in search_pubs
    url = _PUBSEARCH.format(requests.utils.quote(query))
  File "C:\Program Files\WindowsApps\PythonSoftwareFoundation.Python.3.8_3.8.2288.0_x64__qbz5n2kfra8p0\lib\urllib\parse.py", line 850, in quote
    return quote_from_bytes(string, safe)
  File "C:\Program Files\WindowsApps\PythonSoftwareFoundation.Python.3.8_3.8.2288.0_x64__qbz5n2kfra8p0\lib\urllib\parse.py", line 875, in quote_from_bytes
    raise TypeError("quote_from_bytes() expected bytes")
TypeError: quote_from_bytes() expected bytes
INFO:django.utils.autoreload:C:\Users\elisa\OneDrive\Documents\GitHub\research-for-all\rfa\core\views.py changed, reloading.
ERROR:django.request:Internal Server Error: /api/search/
Traceback (most recent call last):
  File "C:\Users\elisa\OneDrive\Documents\GitHub\fm-dashboard\env\lib\site-packages\django\core\handlers\exception.py", line 47, in inner
    response = get_response(request)
  File "C:\Users\elisa\OneDrive\Documents\GitHub\fm-dashboard\env\lib\site-packages\django\core\handlers\base.py", line 181, in _get_response
    response = wrapped_callback(request, *callback_args, **callback_kwargs)
  File "C:\Users\elisa\OneDrive\Documents\GitHub\fm-dashboard\env\lib\site-packages\django\views\decorators\csrf.py", line 54, in wrapped_view
    return view_func(*args, **kwargs)
  File "C:\Users\elisa\OneDrive\Documents\GitHub\fm-dashboard\env\lib\site-packages\django\views\generic\base.py", line 70, in view
    return self.dispatch(request, *args, **kwargs)
  File "C:\Users\elisa\OneDrive\Documents\GitHub\fm-dashboard\env\lib\site-packages\rest_framework\views.py", line 509, in dispatch
    response = self.handle_exception(exc)
  File "C:\Users\elisa\OneDrive\Documents\GitHub\fm-dashboard\env\lib\site-packages\rest_framework\views.py", line 469, in handle_exception
    self.raise_uncaught_exception(exc)
  File "C:\Users\elisa\OneDrive\Documents\GitHub\fm-dashboard\env\lib\site-packages\rest_framework\views.py", line 480, in raise_uncaught_exception
    raise exc
  File "C:\Users\elisa\OneDrive\Documents\GitHub\fm-dashboard\env\lib\site-packages\rest_framework\views.py", line 506, in dispatch
    response = handler(request, *args, **kwargs)
  File "C:\Users\elisa\OneDrive\Documents\GitHub\research-for-all\rfa\core\views.py", line 17, in post
    search_term = request.data['search_term']
KeyError: 'search_term'
ERROR:django.request:Internal Server Error: /api/search/
Traceback (most recent call last):
  File "C:\Users\elisa\OneDrive\Documents\GitHub\fm-dashboard\env\lib\site-packages\django\core\handlers\exception.py", line 47, in inner
    response = get_response(request)
  File "C:\Users\elisa\OneDrive\Documents\GitHub\fm-dashboard\env\lib\site-packages\django\core\handlers\base.py", line 181, in _get_response
    response = wrapped_callback(request, *callback_args, **callback_kwargs)
  File "C:\Users\elisa\OneDrive\Documents\GitHub\fm-dashboard\env\lib\site-packages\django\views\decorators\csrf.py", line 54, in wrapped_view
    return view_func(*args, **kwargs)
  File "C:\Users\elisa\OneDrive\Documents\GitHub\fm-dashboard\env\lib\site-packages\django\views\generic\base.py", line 70, in view
    return self.dispatch(request, *args, **kwargs)
  File "C:\Users\elisa\OneDrive\Documents\GitHub\fm-dashboard\env\lib\site-packages\rest_framework\views.py", line 509, in dispatch
    response = self.handle_exception(exc)
  File "C:\Users\elisa\OneDrive\Documents\GitHub\fm-dashboard\env\lib\site-packages\rest_framework\views.py", line 469, in handle_exception
    self.raise_uncaught_exception(exc)
  File "C:\Users\elisa\OneDrive\Documents\GitHub\fm-dashboard\env\lib\site-packages\rest_framework\views.py", line 480, in raise_uncaught_exception
    raise exc
  File "C:\Users\elisa\OneDrive\Documents\GitHub\fm-dashboard\env\lib\site-packages\rest_framework\views.py", line 506, in dispatch
    response = handler(request, *args, **kwargs)
  File "C:\Users\elisa\OneDrive\Documents\GitHub\research-for-all\rfa\core\views.py", line 22, in post
    search_query = scholarly.search_pubs(search_term)
  File "C:\Users\elisa\OneDrive\Documents\GitHub\fm-dashboard\env\lib\site-packages\scholarly\_scholarly.py", line 145, in search_pubs
    return self.__nav.search_publications(url)
  File "C:\Users\elisa\OneDrive\Documents\GitHub\fm-dashboard\env\lib\site-packages\scholarly\_navigator.py", line 263, in search_publications
    return _SearchScholarIterator(self, url)
  File "C:\Users\elisa\OneDrive\Documents\GitHub\fm-dashboard\env\lib\site-packages\scholarly\publication_parser.py", line 53, in __init__
    self._load_url(url)
  File "C:\Users\elisa\OneDrive\Documents\GitHub\fm-dashboard\env\lib\site-packages\scholarly\publication_parser.py", line 59, in _load_url
    self._soup = self._nav._get_soup(url)
  File "C:\Users\elisa\OneDrive\Documents\GitHub\fm-dashboard\env\lib\site-packages\scholarly\_navigator.py", line 206, in _get_soup
    html = self._get_page('https://scholar.google.com{0}'.format(url))
  File "C:\Users\elisa\OneDrive\Documents\GitHub\fm-dashboard\env\lib\site-packages\scholarly\_navigator.py", line 158, in _get_page
    raise MaxTriesExceededException("Cannot Fetch from Google Scholar.")
scholarly._navigator.MaxTriesExceededException: Cannot Fetch from Google Scholar.
ERROR:django.request:Internal Server Error: /api/search/
Traceback (most recent call last):
  File "C:\Users\elisa\OneDrive\Documents\GitHub\fm-dashboard\env\lib\site-packages\django\core\handlers\exception.py", line 47, in inner
    response = get_response(request)
  File "C:\Users\elisa\OneDrive\Documents\GitHub\fm-dashboard\env\lib\site-packages\django\core\handlers\base.py", line 181, in _get_response
    response = wrapped_callback(request, *callback_args, **callback_kwargs)
  File "C:\Users\elisa\OneDrive\Documents\GitHub\fm-dashboard\env\lib\site-packages\django\views\decorators\csrf.py", line 54, in wrapped_view
    return view_func(*args, **kwargs)
  File "C:\Users\elisa\OneDrive\Documents\GitHub\fm-dashboard\env\lib\site-packages\django\views\generic\base.py", line 70, in view
    return self.dispatch(request, *args, **kwargs)
  File "C:\Users\elisa\OneDrive\Documents\GitHub\fm-dashboard\env\lib\site-packages\rest_framework\views.py", line 509, in dispatch
    response = self.handle_exception(exc)
  File "C:\Users\elisa\OneDrive\Documents\GitHub\fm-dashboard\env\lib\site-packages\rest_framework\views.py", line 469, in handle_exception
    self.raise_uncaught_exception(exc)
  File "C:\Users\elisa\OneDrive\Documents\GitHub\fm-dashboard\env\lib\site-packages\rest_framework\views.py", line 480, in raise_uncaught_exception
    raise exc
  File "C:\Users\elisa\OneDrive\Documents\GitHub\fm-dashboard\env\lib\site-packages\rest_framework\views.py", line 506, in dispatch
    response = handler(request, *args, **kwargs)
  File "C:\Users\elisa\OneDrive\Documents\GitHub\research-for-all\rfa\core\views.py", line 22, in post
    search_query = scholarly.search_pubs(search_term)
  File "C:\Users\elisa\OneDrive\Documents\GitHub\fm-dashboard\env\lib\site-packages\scholarly\_scholarly.py", line 145, in search_pubs
    return self.__nav.search_publications(url)
  File "C:\Users\elisa\OneDrive\Documents\GitHub\fm-dashboard\env\lib\site-packages\scholarly\_navigator.py", line 263, in search_publications
    return _SearchScholarIterator(self, url)
  File "C:\Users\elisa\OneDrive\Documents\GitHub\fm-dashboard\env\lib\site-packages\scholarly\publication_parser.py", line 53, in __init__
    self._load_url(url)
  File "C:\Users\elisa\OneDrive\Documents\GitHub\fm-dashboard\env\lib\site-packages\scholarly\publication_parser.py", line 59, in _load_url
    self._soup = self._nav._get_soup(url)
  File "C:\Users\elisa\OneDrive\Documents\GitHub\fm-dashboard\env\lib\site-packages\scholarly\_navigator.py", line 206, in _get_soup
    html = self._get_page('https://scholar.google.com{0}'.format(url))
  File "C:\Users\elisa\OneDrive\Documents\GitHub\fm-dashboard\env\lib\site-packages\scholarly\_navigator.py", line 158, in _get_page
    raise MaxTriesExceededException("Cannot Fetch from Google Scholar.")
scholarly._navigator.MaxTriesExceededException: Cannot Fetch from Google Scholar.
INFO:django.utils.autoreload:C:\Users\elisa\OneDrive\Documents\GitHub\research-for-all\rfa\core\views.py changed, reloading.
ERROR:django.request:Internal Server Error: /api/search/
Traceback (most recent call last):
  File "C:\Users\elisa\OneDrive\Documents\GitHub\fm-dashboard\env\lib\site-packages\django\core\handlers\exception.py", line 47, in inner
    response = get_response(request)
  File "C:\Users\elisa\OneDrive\Documents\GitHub\fm-dashboard\env\lib\site-packages\django\core\handlers\base.py", line 181, in _get_response
    response = wrapped_callback(request, *callback_args, **callback_kwargs)
  File "C:\Users\elisa\OneDrive\Documents\GitHub\fm-dashboard\env\lib\site-packages\django\views\decorators\csrf.py", line 54, in wrapped_view
    return view_func(*args, **kwargs)
  File "C:\Users\elisa\OneDrive\Documents\GitHub\fm-dashboard\env\lib\site-packages\django\views\generic\base.py", line 70, in view
    return self.dispatch(request, *args, **kwargs)
  File "C:\Users\elisa\OneDrive\Documents\GitHub\fm-dashboard\env\lib\site-packages\rest_framework\views.py", line 509, in dispatch
    response = self.handle_exception(exc)
  File "C:\Users\elisa\OneDrive\Documents\GitHub\fm-dashboard\env\lib\site-packages\rest_framework\views.py", line 469, in handle_exception
    self.raise_uncaught_exception(exc)
  File "C:\Users\elisa\OneDrive\Documents\GitHub\fm-dashboard\env\lib\site-packages\rest_framework\views.py", line 480, in raise_uncaught_exception
    raise exc
  File "C:\Users\elisa\OneDrive\Documents\GitHub\fm-dashboard\env\lib\site-packages\rest_framework\views.py", line 506, in dispatch
    response = handler(request, *args, **kwargs)
  File "C:\Users\elisa\OneDrive\Documents\GitHub\research-for-all\rfa\core\views.py", line 22, in post
    search_query = scholarly.search_pubs(search_term)
  File "C:\Users\elisa\OneDrive\Documents\GitHub\fm-dashboard\env\lib\site-packages\scholarly\_scholarly.py", line 145, in search_pubs
    return self.__nav.search_publications(url)
  File "C:\Users\elisa\OneDrive\Documents\GitHub\fm-dashboard\env\lib\site-packages\scholarly\_navigator.py", line 263, in search_publications
    return _SearchScholarIterator(self, url)
  File "C:\Users\elisa\OneDrive\Documents\GitHub\fm-dashboard\env\lib\site-packages\scholarly\publication_parser.py", line 53, in __init__
    self._load_url(url)
  File "C:\Users\elisa\OneDrive\Documents\GitHub\fm-dashboard\env\lib\site-packages\scholarly\publication_parser.py", line 59, in _load_url
    self._soup = self._nav._get_soup(url)
  File "C:\Users\elisa\OneDrive\Documents\GitHub\fm-dashboard\env\lib\site-packages\scholarly\_navigator.py", line 206, in _get_soup
    html = self._get_page('https://scholar.google.com{0}'.format(url))
  File "C:\Users\elisa\OneDrive\Documents\GitHub\fm-dashboard\env\lib\site-packages\scholarly\_navigator.py", line 158, in _get_page
    raise MaxTriesExceededException("Cannot Fetch from Google Scholar.")
scholarly._navigator.MaxTriesExceededException: Cannot Fetch from Google Scholar.
